Microsoft Windows [Version 10.0.22000.194]
(c) Microsoft Corporation. All rights reserved.

C:\Users\37529>cd c:\Users\37529\vfs-appointment-bot\VFSBot\

c:\Users\37529\vfs-appointment-bot\VFSBot>VFSBot>python-telegram-bot
'VFSBot' is not recognized as an internal or external command,
operable program or batch file.

c:\Users\37529\vfs-appointment-bot\VFSBot>pip install python-telegram-bot
Requirement already satisfied: python-telegram-bot in c:\users\37529\appdata\local\programs\python\python311\lib\site-packages (13.11)
Requirement already satisfied: certifi in c:\users\37529\appdata\local\programs\python\python311\lib\site-packages (from python-telegram-bot) (2023.7.22)
Requirement already satisfied: tornado>=6.1 in c:\users\37529\appdata\local\programs\python\python311\lib\site-packages (from python-telegram-bot) (6.3.2)
Requirement already satisfied: APScheduler==3.6.3 in c:\users\37529\appdata\local\programs\python\python311\lib\site-packages (from python-telegram-bot) (3.6.3)
Requirement already satisfied: pytz>=2018.6 in c:\users\37529\appdata\local\programs\python\python311\lib\site-packages (from python-telegram-bot) (2023.3)
Requirement already satisfied: cachetools==4.2.2 in c:\users\37529\appdata\local\programs\python\python311\lib\site-packages (from python-telegram-bot) (4.2.2)
Requirement already satisfied: setuptools>=0.7 in c:\users\37529\appdata\local\programs\python\python311\lib\site-packages (from APScheduler==3.6.3->python-telegram-bot) (68.0.0)
Requirement already satisfied: six>=1.4.0 in c:\users\37529\appdata\local\programs\python\python311\lib\site-packages (from APScheduler==3.6.3->python-telegram-bot) (1.16.0)
Requirement already satisfied: tzlocal>=1.2 in c:\users\37529\appdata\local\programs\python\python311\lib\site-packages (from APScheduler==3.6.3->python-telegram-bot) (5.0.1)
Requirement already satisfied: tzdata in c:\users\37529\appdata\local\programs\python\python311\lib\site-packages (from tzlocal>=1.2->APScheduler==3.6.3->python-telegram-bot) (2023.3)

c:\Users\37529\vfs-appointment-bot\VFSBot>VFSBot.py
Error while getting Updates: Conflict: terminated by other getUpdates request; make sure that only one bot instance is running
No error handlers are registered, logging exception.
Traceback (most recent call last):
  File "C:\Users\37529\AppData\Local\Programs\Python\Python311\Lib\site-packages\telegram\ext\updater.py", line 646, in _network_loop_retry
    if not action_cb():
           ^^^^^^^^^^^
  File "C:\Users\37529\AppData\Local\Programs\Python\Python311\Lib\site-packages\telegram\ext\updater.py", line 597, in polling_action_cb
    updates = self.bot.get_updates(
              ^^^^^^^^^^^^^^^^^^^^^
  File "C:\Users\37529\AppData\Local\Programs\Python\Python311\Lib\site-packages\telegram\ext\extbot.py", line 224, in get_updates
    updates = super().get_updates(
              ^^^^^^^^^^^^^^^^^^^^
  File "C:\Users\37529\AppData\Local\Programs\Python\Python311\Lib\site-packages\telegram\bot.py", line 130, in decorator
    result = func(*args, **kwargs)
             ^^^^^^^^^^^^^^^^^^^^^
  File "C:\Users\37529\AppData\Local\Programs\Python\Python311\Lib\site-packages\telegram\bot.py", line 3054, in get_updates
    self._post(
  File "C:\Users\37529\AppData\Local\Programs\Python\Python311\Lib\site-packages\telegram\bot.py", line 295, in _post
    return self.request.post(
           ^^^^^^^^^^^^^^^^^^
  File "C:\Users\37529\AppData\Local\Programs\Python\Python311\Lib\site-packages\telegram\utils\request.py", line 361, in post
    result = self._request_wrapper(
             ^^^^^^^^^^^^^^^^^^^^^^
  File "C:\Users\37529\AppData\Local\Programs\Python\Python311\Lib\site-packages\telegram\utils\request.py", line 283, in _request_wrapper
    raise Conflict(message)
telegram.error.Conflict: Conflict: terminated by other getUpdates request; make sure that only one bot instance is running
Error while getting Updates: Conflict: terminated by other getUpdates request; make sure that only one bot instance is running
No error handlers are registered, logging exception.
Traceback (most recent call last):
  File "C:\Users\37529\AppData\Local\Programs\Python\Python311\Lib\site-packages\telegram\ext\updater.py", line 646, in _network_loop_retry
    if not action_cb():
           ^^^^^^^^^^^
  File "C:\Users\37529\AppData\Local\Programs\Python\Python311\Lib\site-packages\telegram\ext\updater.py", line 597, in polling_action_cb
    updates = self.bot.get_updates(
              ^^^^^^^^^^^^^^^^^^^^^
  File "C:\Users\37529\AppData\Local\Programs\Python\Python311\Lib\site-packages\telegram\ext\extbot.py", line 224, in get_updates
    updates = super().get_updates(
              ^^^^^^^^^^^^^^^^^^^^
  File "C:\Users\37529\AppData\Local\Programs\Python\Python311\Lib\site-packages\telegram\bot.py", line 130, in decorator
    result = func(*args, **kwargs)
             ^^^^^^^^^^^^^^^^^^^^^
  File "C:\Users\37529\AppData\Local\Programs\Python\Python311\Lib\site-packages\telegram\bot.py", line 3054, in get_updates
    self._post(
  File "C:\Users\37529\AppData\Local\Programs\Python\Python311\Lib\site-packages\telegram\bot.py", line 295, in _post
    return self.request.post(
           ^^^^^^^^^^^^^^^^^^
  File "C:\Users\37529\AppData\Local\Programs\Python\Python311\Lib\site-packages\telegram\utils\request.py", line 361, in post
    result = self._request_wrapper(
             ^^^^^^^^^^^^^^^^^^^^^^
  File "C:\Users\37529\AppData\Local\Programs\Python\Python311\Lib\site-packages\telegram\utils\request.py", line 283, in _request_wrapper
    raise Conflict(message)
telegram.error.Conflict: Conflict: terminated by other getUpdates request; make sure that only one bot instance is running
Error while getting Updates: Conflict: terminated by other getUpdates request; make sure that only one bot instance is running
No error handlers are registered, logging exception.
Traceback (most recent call last):
  File "C:\Users\37529\AppData\Local\Programs\Python\Python311\Lib\site-packages\telegram\ext\updater.py", line 646, in _network_loop_retry
    if not action_cb():
           ^^^^^^^^^^^
  File "C:\Users\37529\AppData\Local\Programs\Python\Python311\Lib\site-packages\telegram\ext\updater.py", line 597, in polling_action_cb
    updates = self.bot.get_updates(
              ^^^^^^^^^^^^^^^^^^^^^
  File "C:\Users\37529\AppData\Local\Programs\Python\Python311\Lib\site-packages\telegram\ext\extbot.py", line 224, in get_updates
    updates = super().get_updates(
              ^^^^^^^^^^^^^^^^^^^^
  File "C:\Users\37529\AppData\Local\Programs\Python\Python311\Lib\site-packages\telegram\bot.py", line 130, in decorator
    result = func(*args, **kwargs)
             ^^^^^^^^^^^^^^^^^^^^^
  File "C:\Users\37529\AppData\Local\Programs\Python\Python311\Lib\site-packages\telegram\bot.py", line 3054, in get_updates
    self._post(
  File "C:\Users\37529\AppData\Local\Programs\Python\Python311\Lib\site-packages\telegram\bot.py", line 295, in _post
    return self.request.post(
           ^^^^^^^^^^^^^^^^^^
  File "C:\Users\37529\AppData\Local\Programs\Python\Python311\Lib\site-packages\telegram\utils\request.py", line 361, in post
    result = self._request_wrapper(
             ^^^^^^^^^^^^^^^^^^^^^^
  File "C:\Users\37529\AppData\Local\Programs\Python\Python311\Lib\site-packages\telegram\utils\request.py", line 283, in _request_wrapper
    raise Conflict(message)
telegram.error.Conflict: Conflict: terminated by other getUpdates request; make sure that only one bot instance is running
Error while getting Updates: Conflict: terminated by other getUpdates request; make sure that only one bot instance is running
No error handlers are registered, logging exception.
Traceback (most recent call last):
  File "C:\Users\37529\AppData\Local\Programs\Python\Python311\Lib\site-packages\telegram\ext\updater.py", line 646, in _network_loop_retry
    if not action_cb():
           ^^^^^^^^^^^
  File "C:\Users\37529\AppData\Local\Programs\Python\Python311\Lib\site-packages\telegram\ext\updater.py", line 597, in polling_action_cb
    updates = self.bot.get_updates(
              ^^^^^^^^^^^^^^^^^^^^^
  File "C:\Users\37529\AppData\Local\Programs\Python\Python311\Lib\site-packages\telegram\ext\extbot.py", line 224, in get_updates
    updates = super().get_updates(
              ^^^^^^^^^^^^^^^^^^^^
  File "C:\Users\37529\AppData\Local\Programs\Python\Python311\Lib\site-packages\telegram\bot.py", line 130, in decorator
    result = func(*args, **kwargs)
             ^^^^^^^^^^^^^^^^^^^^^
  File "C:\Users\37529\AppData\Local\Programs\Python\Python311\Lib\site-packages\telegram\bot.py", line 3054, in get_updates
    self._post(
  File "C:\Users\37529\AppData\Local\Programs\Python\Python311\Lib\site-packages\telegram\bot.py", line 295, in _post
    return self.request.post(
           ^^^^^^^^^^^^^^^^^^
  File "C:\Users\37529\AppData\Local\Programs\Python\Python311\Lib\site-packages\telegram\utils\request.py", line 361, in post
    result = self._request_wrapper(
             ^^^^^^^^^^^^^^^^^^^^^^
  File "C:\Users\37529\AppData\Local\Programs\Python\Python311\Lib\site-packages\telegram\utils\request.py", line 283, in _request_wrapper
    raise Conflict(message)
telegram.error.Conflict: Conflict: terminated by other getUpdates request; make sure that only one bot instance is running
Error while getting Updates: Conflict: terminated by other getUpdates request; make sure that only one bot instance is running
No error handlers are registered, logging exception.
Traceback (most recent call last):
  File "C:\Users\37529\AppData\Local\Programs\Python\Python311\Lib\site-packages\telegram\ext\updater.py", line 646, in _network_loop_retry
    if not action_cb():
           ^^^^^^^^^^^
  File "C:\Users\37529\AppData\Local\Programs\Python\Python311\Lib\site-packages\telegram\ext\updater.py", line 597, in polling_action_cb
    updates = self.bot.get_updates(
              ^^^^^^^^^^^^^^^^^^^^^
  File "C:\Users\37529\AppData\Local\Programs\Python\Python311\Lib\site-packages\telegram\ext\extbot.py", line 224, in get_updates
    updates = super().get_updates(
              ^^^^^^^^^^^^^^^^^^^^
  File "C:\Users\37529\AppData\Local\Programs\Python\Python311\Lib\site-packages\telegram\bot.py", line 130, in decorator
    result = func(*args, **kwargs)
             ^^^^^^^^^^^^^^^^^^^^^
  File "C:\Users\37529\AppData\Local\Programs\Python\Python311\Lib\site-packages\telegram\bot.py", line 3054, in get_updates
    self._post(
  File "C:\Users\37529\AppData\Local\Programs\Python\Python311\Lib\site-packages\telegram\bot.py", line 295, in _post
    return self.request.post(
           ^^^^^^^^^^^^^^^^^^
  File "C:\Users\37529\AppData\Local\Programs\Python\Python311\Lib\site-packages\telegram\utils\request.py", line 361, in post
    result = self._request_wrapper(
             ^^^^^^^^^^^^^^^^^^^^^^
  File "C:\Users\37529\AppData\Local\Programs\Python\Python311\Lib\site-packages\telegram\utils\request.py", line 283, in _request_wrapper
    raise Conflict(message)
telegram.error.Conflict: Conflict: terminated by other getUpdates request; make sure that only one bot instance is running
Error while getting Updates: Conflict: terminated by other getUpdates request; make sure that only one bot instance is running
No error handlers are registered, logging exception.
Traceback (most recent call last):
  File "C:\Users\37529\AppData\Local\Programs\Python\Python311\Lib\site-packages\telegram\ext\updater.py", line 646, in _network_loop_retry
    if not action_cb():
           ^^^^^^^^^^^
  File "C:\Users\37529\AppData\Local\Programs\Python\Python311\Lib\site-packages\telegram\ext\updater.py", line 597, in polling_action_cb
    updates = self.bot.get_updates(
              ^^^^^^^^^^^^^^^^^^^^^
  File "C:\Users\37529\AppData\Local\Programs\Python\Python311\Lib\site-packages\telegram\ext\extbot.py", line 224, in get_updates
    updates = super().get_updates(
              ^^^^^^^^^^^^^^^^^^^^
  File "C:\Users\37529\AppData\Local\Programs\Python\Python311\Lib\site-packages\telegram\bot.py", line 130, in decorator
    result = func(*args, **kwargs)
             ^^^^^^^^^^^^^^^^^^^^^
  File "C:\Users\37529\AppData\Local\Programs\Python\Python311\Lib\site-packages\telegram\bot.py", line 3054, in get_updates
    self._post(
  File "C:\Users\37529\AppData\Local\Programs\Python\Python311\Lib\site-packages\telegram\bot.py", line 295, in _post
    return self.request.post(
           ^^^^^^^^^^^^^^^^^^
  File "C:\Users\37529\AppData\Local\Programs\Python\Python311\Lib\site-packages\telegram\utils\request.py", line 361, in post
    result = self._request_wrapper(
             ^^^^^^^^^^^^^^^^^^^^^^
  File "C:\Users\37529\AppData\Local\Programs\Python\Python311\Lib\site-packages\telegram\utils\request.py", line 283, in _request_wrapper
    raise Conflict(message)
telegram.error.Conflict: Conflict: terminated by other getUpdates request; make sure that only one bot instance is running
Error while getting Updates: Conflict: terminated by other getUpdates request; make sure that only one bot instance is running
No error handlers are registered, logging exception.
Traceback (most recent call last):
  File "C:\Users\37529\AppData\Local\Programs\Python\Python311\Lib\site-packages\telegram\ext\updater.py", line 646, in _network_loop_retry
    if not action_cb():
           ^^^^^^^^^^^
  File "C:\Users\37529\AppData\Local\Programs\Python\Python311\Lib\site-packages\telegram\ext\updater.py", line 597, in polling_action_cb
    updates = self.bot.get_updates(
              ^^^^^^^^^^^^^^^^^^^^^
  File "C:\Users\37529\AppData\Local\Programs\Python\Python311\Lib\site-packages\telegram\ext\extbot.py", line 224, in get_updates
    updates = super().get_updates(
              ^^^^^^^^^^^^^^^^^^^^
  File "C:\Users\37529\AppData\Local\Programs\Python\Python311\Lib\site-packages\telegram\bot.py", line 130, in decorator
    result = func(*args, **kwargs)
             ^^^^^^^^^^^^^^^^^^^^^
  File "C:\Users\37529\AppData\Local\Programs\Python\Python311\Lib\site-packages\telegram\bot.py", line 3054, in get_updates
    self._post(
  File "C:\Users\37529\AppData\Local\Programs\Python\Python311\Lib\site-packages\telegram\bot.py", line 295, in _post
    return self.request.post(
           ^^^^^^^^^^^^^^^^^^
  File "C:\Users\37529\AppData\Local\Programs\Python\Python311\Lib\site-packages\telegram\utils\request.py", line 361, in post
    result = self._request_wrapper(
             ^^^^^^^^^^^^^^^^^^^^^^
  File "C:\Users\37529\AppData\Local\Programs\Python\Python311\Lib\site-packages\telegram\utils\request.py", line 283, in _request_wrapper
    raise Conflict(message)
telegram.error.Conflict: Conflict: terminated by other getUpdates request; make sure that only one bot instance is running
Error while getting Updates: Conflict: terminated by other getUpdates request; make sure that only one bot instance is running
No error handlers are registered, logging exception.
Traceback (most recent call last):
  File "C:\Users\37529\AppData\Local\Programs\Python\Python311\Lib\site-packages\telegram\ext\updater.py", line 646, in _network_loop_retry
    if not action_cb():
           ^^^^^^^^^^^
  File "C:\Users\37529\AppData\Local\Programs\Python\Python311\Lib\site-packages\telegram\ext\updater.py", line 597, in polling_action_cb
    updates = self.bot.get_updates(
              ^^^^^^^^^^^^^^^^^^^^^
  File "C:\Users\37529\AppData\Local\Programs\Python\Python311\Lib\site-packages\telegram\ext\extbot.py", line 224, in get_updates
    updates = super().get_updates(
              ^^^^^^^^^^^^^^^^^^^^
  File "C:\Users\37529\AppData\Local\Programs\Python\Python311\Lib\site-packages\telegram\bot.py", line 130, in decorator
    result = func(*args, **kwargs)
             ^^^^^^^^^^^^^^^^^^^^^
  File "C:\Users\37529\AppData\Local\Programs\Python\Python311\Lib\site-packages\telegram\bot.py", line 3054, in get_updates
    self._post(
  File "C:\Users\37529\AppData\Local\Programs\Python\Python311\Lib\site-packages\telegram\bot.py", line 295, in _post
    return self.request.post(
           ^^^^^^^^^^^^^^^^^^
  File "C:\Users\37529\AppData\Local\Programs\Python\Python311\Lib\site-packages\telegram\utils\request.py", line 361, in post
    result = self._request_wrapper(
             ^^^^^^^^^^^^^^^^^^^^^^
  File "C:\Users\37529\AppData\Local\Programs\Python\Python311\Lib\site-packages\telegram\utils\request.py", line 283, in _request_wrapper
    raise Conflict(message)
telegram.error.Conflict: Conflict: terminated by other getUpdates request; make sure that only one bot instance is running
Error while getting Updates: Conflict: terminated by other getUpdates request; make sure that only one bot instance is running
No error handlers are registered, logging exception.
Traceback (most recent call last):
  File "C:\Users\37529\AppData\Local\Programs\Python\Python311\Lib\site-packages\telegram\ext\updater.py", line 646, in _network_loop_retry
    if not action_cb():
           ^^^^^^^^^^^
  File "C:\Users\37529\AppData\Local\Programs\Python\Python311\Lib\site-packages\telegram\ext\updater.py", line 597, in polling_action_cb
    updates = self.bot.get_updates(
              ^^^^^^^^^^^^^^^^^^^^^
  File "C:\Users\37529\AppData\Local\Programs\Python\Python311\Lib\site-packages\telegram\ext\extbot.py", line 224, in get_updates
    updates = super().get_updates(
              ^^^^^^^^^^^^^^^^^^^^
  File "C:\Users\37529\AppData\Local\Programs\Python\Python311\Lib\site-packages\telegram\bot.py", line 130, in decorator
    result = func(*args, **kwargs)
             ^^^^^^^^^^^^^^^^^^^^^
  File "C:\Users\37529\AppData\Local\Programs\Python\Python311\Lib\site-packages\telegram\bot.py", line 3054, in get_updates
    self._post(
  File "C:\Users\37529\AppData\Local\Programs\Python\Python311\Lib\site-packages\telegram\bot.py", line 295, in _post
    return self.request.post(
           ^^^^^^^^^^^^^^^^^^
  File "C:\Users\37529\AppData\Local\Programs\Python\Python311\Lib\site-packages\telegram\utils\request.py", line 361, in post
    result = self._request_wrapper(
             ^^^^^^^^^^^^^^^^^^^^^^
  File "C:\Users\37529\AppData\Local\Programs\Python\Python311\Lib\site-packages\telegram\utils\request.py", line 283, in _request_wrapper
    raise Conflict(message)
telegram.error.Conflict: Conflict: terminated by other getUpdates request; make sure that only one bot instance is running
Error while getting Updates: Conflict: terminated by other getUpdates request; make sure that only one bot instance is running
No error handlers are registered, logging exception.
Traceback (most recent call last):
  File "C:\Users\37529\AppData\Local\Programs\Python\Python311\Lib\site-packages\telegram\ext\updater.py", line 646, in _network_loop_retry
    if not action_cb():
           ^^^^^^^^^^^
  File "C:\Users\37529\AppData\Local\Programs\Python\Python311\Lib\site-packages\telegram\ext\updater.py", line 597, in polling_action_cb
    updates = self.bot.get_updates(
              ^^^^^^^^^^^^^^^^^^^^^
  File "C:\Users\37529\AppData\Local\Programs\Python\Python311\Lib\site-packages\telegram\ext\extbot.py", line 224, in get_updates
    updates = super().get_updates(
              ^^^^^^^^^^^^^^^^^^^^
  File "C:\Users\37529\AppData\Local\Programs\Python\Python311\Lib\site-packages\telegram\bot.py", line 130, in decorator
    result = func(*args, **kwargs)
             ^^^^^^^^^^^^^^^^^^^^^
  File "C:\Users\37529\AppData\Local\Programs\Python\Python311\Lib\site-packages\telegram\bot.py", line 3054, in get_updates
    self._post(
  File "C:\Users\37529\AppData\Local\Programs\Python\Python311\Lib\site-packages\telegram\bot.py", line 295, in _post
    return self.request.post(
           ^^^^^^^^^^^^^^^^^^
  File "C:\Users\37529\AppData\Local\Programs\Python\Python311\Lib\site-packages\telegram\utils\request.py", line 361, in post
    result = self._request_wrapper(
             ^^^^^^^^^^^^^^^^^^^^^^
  File "C:\Users\37529\AppData\Local\Programs\Python\Python311\Lib\site-packages\telegram\utils\request.py", line 283, in _request_wrapper
    raise Conflict(message)
telegram.error.Conflict: Conflict: terminated by other getUpdates request; make sure that only one bot instance is running
Error while getting Updates: Conflict: terminated by other getUpdates request; make sure that only one bot instance is running
No error handlers are registered, logging exception.
Traceback (most recent call last):
  File "C:\Users\37529\AppData\Local\Programs\Python\Python311\Lib\site-packages\telegram\ext\updater.py", line 646, in _network_loop_retry
    if not action_cb():
           ^^^^^^^^^^^
  File "C:\Users\37529\AppData\Local\Programs\Python\Python311\Lib\site-packages\telegram\ext\updater.py", line 597, in polling_action_cb
    updates = self.bot.get_updates(
              ^^^^^^^^^^^^^^^^^^^^^
  File "C:\Users\37529\AppData\Local\Programs\Python\Python311\Lib\site-packages\telegram\ext\extbot.py", line 224, in get_updates
    updates = super().get_updates(
              ^^^^^^^^^^^^^^^^^^^^
  File "C:\Users\37529\AppData\Local\Programs\Python\Python311\Lib\site-packages\telegram\bot.py", line 130, in decorator
    result = func(*args, **kwargs)
             ^^^^^^^^^^^^^^^^^^^^^
  File "C:\Users\37529\AppData\Local\Programs\Python\Python311\Lib\site-packages\telegram\bot.py", line 3054, in get_updates
    self._post(
  File "C:\Users\37529\AppData\Local\Programs\Python\Python311\Lib\site-packages\telegram\bot.py", line 295, in _post
    return self.request.post(
           ^^^^^^^^^^^^^^^^^^
  File "C:\Users\37529\AppData\Local\Programs\Python\Python311\Lib\site-packages\telegram\utils\request.py", line 361, in post
    result = self._request_wrapper(
             ^^^^^^^^^^^^^^^^^^^^^^
  File "C:\Users\37529\AppData\Local\Programs\Python\Python311\Lib\site-packages\telegram\utils\request.py", line 283, in _request_wrapper
    raise Conflict(message)
telegram.error.Conflict: Conflict: terminated by other getUpdates request; make sure that only one bot instance is running
Error while getting Updates: Conflict: terminated by other getUpdates request; make sure that only one bot instance is running
No error handlers are registered, logging exception.
Traceback (most recent call last):
  File "C:\Users\37529\AppData\Local\Programs\Python\Python311\Lib\site-packages\telegram\ext\updater.py", line 646, in _network_loop_retry
    if not action_cb():
           ^^^^^^^^^^^
  File "C:\Users\37529\AppData\Local\Programs\Python\Python311\Lib\site-packages\telegram\ext\updater.py", line 597, in polling_action_cb
    updates = self.bot.get_updates(
              ^^^^^^^^^^^^^^^^^^^^^
  File "C:\Users\37529\AppData\Local\Programs\Python\Python311\Lib\site-packages\telegram\ext\extbot.py", line 224, in get_updates
    updates = super().get_updates(
              ^^^^^^^^^^^^^^^^^^^^
  File "C:\Users\37529\AppData\Local\Programs\Python\Python311\Lib\site-packages\telegram\bot.py", line 130, in decorator
    result = func(*args, **kwargs)
             ^^^^^^^^^^^^^^^^^^^^^
  File "C:\Users\37529\AppData\Local\Programs\Python\Python311\Lib\site-packages\telegram\bot.py", line 3054, in get_updates
    self._post(
  File "C:\Users\37529\AppData\Local\Programs\Python\Python311\Lib\site-packages\telegram\bot.py", line 295, in _post
    return self.request.post(
           ^^^^^^^^^^^^^^^^^^
  File "C:\Users\37529\AppData\Local\Programs\Python\Python311\Lib\site-packages\telegram\utils\request.py", line 361, in post
    result = self._request_wrapper(
             ^^^^^^^^^^^^^^^^^^^^^^
  File "C:\Users\37529\AppData\Local\Programs\Python\Python311\Lib\site-packages\telegram\utils\request.py", line 283, in _request_wrapper
    raise Conflict(message)
telegram.error.Conflict: Conflict: terminated by other getUpdates request; make sure that only one bot instance is running
Error while getting Updates: Conflict: terminated by other getUpdates request; make sure that only one bot instance is running
No error handlers are registered, logging exception.
Traceback (most recent call last):
  File "C:\Users\37529\AppData\Local\Programs\Python\Python311\Lib\site-packages\telegram\ext\updater.py", line 646, in _network_loop_retry
    if not action_cb():
           ^^^^^^^^^^^
  File "C:\Users\37529\AppData\Local\Programs\Python\Python311\Lib\site-packages\telegram\ext\updater.py", line 597, in polling_action_cb
    updates = self.bot.get_updates(
              ^^^^^^^^^^^^^^^^^^^^^
  File "C:\Users\37529\AppData\Local\Programs\Python\Python311\Lib\site-packages\telegram\ext\extbot.py", line 224, in get_updates
    updates = super().get_updates(
              ^^^^^^^^^^^^^^^^^^^^
  File "C:\Users\37529\AppData\Local\Programs\Python\Python311\Lib\site-packages\telegram\bot.py", line 130, in decorator
    result = func(*args, **kwargs)
             ^^^^^^^^^^^^^^^^^^^^^
  File "C:\Users\37529\AppData\Local\Programs\Python\Python311\Lib\site-packages\telegram\bot.py", line 3054, in get_updates
    self._post(
  File "C:\Users\37529\AppData\Local\Programs\Python\Python311\Lib\site-packages\telegram\bot.py", line 295, in _post
    return self.request.post(
           ^^^^^^^^^^^^^^^^^^
  File "C:\Users\37529\AppData\Local\Programs\Python\Python311\Lib\site-packages\telegram\utils\request.py", line 361, in post
    result = self._request_wrapper(
             ^^^^^^^^^^^^^^^^^^^^^^
  File "C:\Users\37529\AppData\Local\Programs\Python\Python311\Lib\site-packages\telegram\utils\request.py", line 283, in _request_wrapper
    raise Conflict(message)
telegram.error.Conflict: Conflict: terminated by other getUpdates request; make sure that only one bot instance is running
Error while getting Updates: Conflict: terminated by other getUpdates request; make sure that only one bot instance is running
No error handlers are registered, logging exception.
Traceback (most recent call last):
  File "C:\Users\37529\AppData\Local\Programs\Python\Python311\Lib\site-packages\telegram\ext\updater.py", line 646, in _network_loop_retry
    if not action_cb():
           ^^^^^^^^^^^
  File "C:\Users\37529\AppData\Local\Programs\Python\Python311\Lib\site-packages\telegram\ext\updater.py", line 597, in polling_action_cb
    updates = self.bot.get_updates(
              ^^^^^^^^^^^^^^^^^^^^^
  File "C:\Users\37529\AppData\Local\Programs\Python\Python311\Lib\site-packages\telegram\ext\extbot.py", line 224, in get_updates
    updates = super().get_updates(
              ^^^^^^^^^^^^^^^^^^^^
  File "C:\Users\37529\AppData\Local\Programs\Python\Python311\Lib\site-packages\telegram\bot.py", line 130, in decorator
    result = func(*args, **kwargs)
             ^^^^^^^^^^^^^^^^^^^^^
  File "C:\Users\37529\AppData\Local\Programs\Python\Python311\Lib\site-packages\telegram\bot.py", line 3054, in get_updates
    self._post(
  File "C:\Users\37529\AppData\Local\Programs\Python\Python311\Lib\site-packages\telegram\bot.py", line 295, in _post
    return self.request.post(
           ^^^^^^^^^^^^^^^^^^
  File "C:\Users\37529\AppData\Local\Programs\Python\Python311\Lib\site-packages\telegram\utils\request.py", line 361, in post
    result = self._request_wrapper(
             ^^^^^^^^^^^^^^^^^^^^^^
  File "C:\Users\37529\AppData\Local\Programs\Python\Python311\Lib\site-packages\telegram\utils\request.py", line 283, in _request_wrapper
    raise Conflict(message)
telegram.error.Conflict: Conflict: terminated by other getUpdates request; make sure that only one bot instance is running
Error while getting Updates: Conflict: terminated by other getUpdates request; make sure that only one bot instance is running
No error handlers are registered, logging exception.
Traceback (most recent call last):
  File "C:\Users\37529\AppData\Local\Programs\Python\Python311\Lib\site-packages\telegram\ext\updater.py", line 646, in _network_loop_retry
    if not action_cb():
           ^^^^^^^^^^^
  File "C:\Users\37529\AppData\Local\Programs\Python\Python311\Lib\site-packages\telegram\ext\updater.py", line 597, in polling_action_cb
    updates = self.bot.get_updates(
              ^^^^^^^^^^^^^^^^^^^^^
  File "C:\Users\37529\AppData\Local\Programs\Python\Python311\Lib\site-packages\telegram\ext\extbot.py", line 224, in get_updates
    updates = super().get_updates(
              ^^^^^^^^^^^^^^^^^^^^
  File "C:\Users\37529\AppData\Local\Programs\Python\Python311\Lib\site-packages\telegram\bot.py", line 130, in decorator
    result = func(*args, **kwargs)
             ^^^^^^^^^^^^^^^^^^^^^
  File "C:\Users\37529\AppData\Local\Programs\Python\Python311\Lib\site-packages\telegram\bot.py", line 3054, in get_updates
    self._post(
  File "C:\Users\37529\AppData\Local\Programs\Python\Python311\Lib\site-packages\telegram\bot.py", line 295, in _post
    return self.request.post(
           ^^^^^^^^^^^^^^^^^^
  File "C:\Users\37529\AppData\Local\Programs\Python\Python311\Lib\site-packages\telegram\utils\request.py", line 361, in post
    result = self._request_wrapper(
             ^^^^^^^^^^^^^^^^^^^^^^
  File "C:\Users\37529\AppData\Local\Programs\Python\Python311\Lib\site-packages\telegram\utils\request.py", line 283, in _request_wrapper
    raise Conflict(message)
telegram.error.Conflict: Conflict: terminated by other getUpdates request; make sure that only one bot instance is running
Error while getting Updates: Conflict: terminated by other getUpdates request; make sure that only one bot instance is running
No error handlers are registered, logging exception.
Traceback (most recent call last):
  File "C:\Users\37529\AppData\Local\Programs\Python\Python311\Lib\site-packages\telegram\ext\updater.py", line 646, in _network_loop_retry
    if not action_cb():
           ^^^^^^^^^^^
  File "C:\Users\37529\AppData\Local\Programs\Python\Python311\Lib\site-packages\telegram\ext\updater.py", line 597, in polling_action_cb
    updates = self.bot.get_updates(
              ^^^^^^^^^^^^^^^^^^^^^
  File "C:\Users\37529\AppData\Local\Programs\Python\Python311\Lib\site-packages\telegram\ext\extbot.py", line 224, in get_updates
    updates = super().get_updates(
              ^^^^^^^^^^^^^^^^^^^^
  File "C:\Users\37529\AppData\Local\Programs\Python\Python311\Lib\site-packages\telegram\bot.py", line 130, in decorator
    result = func(*args, **kwargs)
             ^^^^^^^^^^^^^^^^^^^^^
  File "C:\Users\37529\AppData\Local\Programs\Python\Python311\Lib\site-packages\telegram\bot.py", line 3054, in get_updates
    self._post(
  File "C:\Users\37529\AppData\Local\Programs\Python\Python311\Lib\site-packages\telegram\bot.py", line 295, in _post
    return self.request.post(
           ^^^^^^^^^^^^^^^^^^
  File "C:\Users\37529\AppData\Local\Programs\Python\Python311\Lib\site-packages\telegram\utils\request.py", line 361, in post
    result = self._request_wrapper(
             ^^^^^^^^^^^^^^^^^^^^^^
  File "C:\Users\37529\AppData\Local\Programs\Python\Python311\Lib\site-packages\telegram\utils\request.py", line 283, in _request_wrapper
    raise Conflict(message)
telegram.error.Conflict: Conflict: terminated by other getUpdates request; make sure that only one bot instance is running
